Workbook

Sheet Employment Share
F1: Employment Share | O1: LS Part-Time
B2: Operator | D2: Agr | F2: Rural nonagr | H2: Urban nonagr | J2: A + R | L2: A + U | O2: Rural | U2: Urban | AA2: Both
A4: 2003
A5: 2004 | B5: 0.27552488 | C5: 0.002010314 | D5: 0.21519731 | E5: 0.0015904634 | F5: 0.14785695 | G5: 0.0019212065 | H5: 0.15445596 | I5: 0.0017735433 | J5: 0.1589642 | K5: 0.0015752087 | L5: 0.048000697 | M5: 0.00099239871 | O5: 0.38813826 | P5: 0.0032353518 | Q5: 0.33333334 | R5: 0.0029493147 | S5: 0.27049732 | T5: 0.4861111 | U5: 0.2627818 | V5: 0.0041026375 | W5: 0.2 | X5: 0.0042978111 | Y5: 0.19850528 | Z5: 0.24945056 | AA5: 0.35906473 | AB5: 0.0024410614 | AC5: 0.2857143 | AD5: 0.0033414988 | AE5: 0.26102209 | AF5: 0.43447748
A6: 2005 | B6: 0.27360517 | C6: 0.0023950415 | D6: 0.21182606 | E6: 0.001966608 | F6: 0.14696006 | G6: 0.0015682337 | H6: 0.16251956 | I6: 0.0016733593 | J6: 0.15820211 | K6: 0.0017428856 | L6: 0.046887059 | M6: 0.0011288964 | O6: 0.38339731 | P6: 0.0028398363 | Q6: 0.31746033 | R6: 0.0092215575 | S6: 0.27374682 | T6: 0.48801368 | U6: 0.26482311 | V6: 0.0042264466 | W6: 0.2 | X6: 0.0052306531 | Y6: 0.20389451 | Z6: 0.26973683 | AA6: 0.35628912 | AB6: 0.0028127192 | AC6: 0.2739726 | AD6: 0.0048276107 | AE6: 0.26416728 | AF6: 0.4464286
A7: 2006 | B7: 0.26587328 | C7: 0.0019038107 | D7: 0.20428693 | E7: 0.0020022283 | F7: 0.14953865 | G7: 0.0015414505 | H7: 0.18153724 | I7: 0.001847813 | J7: 0.15091941 | K7: 0.0014391569 | L7: 0.047844477 | M7: 0.0010190021 | O7: 0.36885911 | P7: 0.0031439881 | Q7: 0.29411766 | R7: 0.0081391372 | S7: 0.2658138 | T7: 0.45289853 | U7: 0.25568959 | V7: 0.0039564292 | W7: 0.17647059 | X7: 0.0070804469 | Y7: 0.20499621 | Z7: 0.23558898 | AA7: 0.34161806 | AB7: 0.0030610349 | AC7: 0.25 | AD7: 0.0043100864 | AE7: 0.25709969 | AF7: 0.41360295
A8: 2007 | B8: 0.25412574 | C8: 0.0019423191 | D8: 0.19387311 | E8: 0.0019309951 | F8: 0.1502686 | G8: 0.0018138132 | H8: 0.19757538 | I8: 0.0019063398 | J8: 0.15440643 | K8: 0.0016823316 | L8: 0.049750764 | M8: 0.0011130184 | O8: 0.35351658 | P8: 0.0030702029 | Q8: 0.26666668 | R8: 0.0092065707 | S8: 0.26509795 | T8: 0.45378155 | U8: 0.24313608 | V8: 0.0041239248 | W8: 0.16666667 | X8: 0.0026014138 | Y8: 0.19940744 | Z8: 0.24242425 | AA8: 0.32661811 | AB8: 0.0025476187 | AC8: 0.23076923 | AD8: 0.0035748801 | AE8: 0.25511038 | AF8: 0.3888889
A9: 2008 | B9: 0.24967597 | C9: 0.0022335381 | D9: 0.20141393 | E9: 0.0017928404 | F9: 0.15956168 | G9: 0.0018236351 | H9: 0.19934016 | I9: 0.001686983 | J9: 0.14391422 | K9: 0.0016240312 | L9: 0.046094026 | M9: 0.0010554931 | O9: 0.3479605 | P9: 0.0034741191 | Q9: 0.25 | R9: 0.0061601405 | S9: 0.26422423 | T9: 0.43987507 | U9: 0.22925907 | V9: 0.004504181 | W9: 0.16666667 | X9: 0.00022831112 | Y9: 0.1810028 | Z9: 0.22051331 | AA9: 0.31916478 | AB9: 0.0028012218 | AC9: 0.22727273 | AD9: 0.0043405648 | AE9: 0.25181332 | AF9: 0.39108911
A10: 2009 | B10: 0.2377851 | C10: 0.0021951424 | D10: 0.20288195 | E10: 0.0018592447 | F10: 0.17053154 | G10: 0.0019762032 | H10: 0.20963356 | I10: 0.0018730301 | J10: 0.13734612 | K10: 0.0019394348 | L10: 0.041821741 | M10: 0.00095171155 | O10: 0.34269661 | P10: 0.0040335865 | Q10: 0.23076923 | R10: 0.0054862862 | S10: 0.2688615 | T10: 0.45068663 | U10: 0.20559901 | V10: 0.0038315433 | W10: 0.14285715 | X10: 0.002040558 | Y10: 0.16958889 | Z10: 0.16936487 | AA10: 0.31069499 | AB10: 0.0031925121 | AC10: 0.2 | AD10: 0.00090191461 | AE10: 0.25590047 | AF10: 0.40000001
A11: 2010 | B11: 0.23234458 | C11: 0.0022143743 | D11: 0.19782625 | E11: 0.0018834559 | F11: 0.17991295 | G11: 0.0018690157 | H11: 0.21616726 | I11: 0.001974632 | J11: 0.13261378 | K11: 0.0016097367 | L11: 0.041135181 | M11: 0.0010250335 | O11: 0.34196052 | P11: 0.004039722 | Q11: 0.23076923 | R11: 0.0069717499 | S11: 0.27048701 | T11: 0.44444448 | U11: 0.20013088 | V11: 0.0044993889 | W11: 0.13043478 | X11: 0.0048504439 | Y11: 0.17017134 | Z11: 0.16228071 | AA11: 0.30838224 | AB11: 0.0031078923 | AC11: 0.2 | AD11: 0.0018355211 | AE11: 0.25754103 | AF11: 0.39637649
A12: 2011 | B12: 0.2293222 | C12: 0.0023733827 | D12: 0.19330497 | E12: 0.00224113 | F12: 0.18591957 | G12: 0.0021297445 | H12: 0.21669209 | I12: 0.0022151819 | J12: 0.13459635 | K12: 0.0017872098 | L12: 0.040164832 | M12: 0.00095493445 | O12: 0.32493231 | P12: 0.0035512936 | Q12: 0.21917808 | R12: 0.0070743561 | S12: 0.26122901 | T12: 0.41404921 | U12: 0.18778467 | V12: 0.004543276 | W12: 0.13043478 | X12: 0.0029293569 | Y12: 0.15815429 | Z12: 0.1474359 | AA12: 0.29341209 | AB12: 0.0030141592 | AC12: 0.18495297 | AD12: 0.0048071123 | AE12: 0.24825436 | AF12: 0.3416096
A13: 2012 | B13: 0.22787952 | C13: 0.0020805311 | D13: 0.19149934 | E13: 0.0021207631 | F13: 0.19166483 | G13: 0.0020104116 | H13: 0.22021183 | I13: 0.0021239186 | J13: 0.1297992 | K13: 0.0019211007 | L13: 0.038945276 | M13: 0.001006691 | O13: 0.31191623 | P13: 0.0039623627 | Q13: 0.21505377 | R13: 0.0070855878 | S13: 0.25293258 | T13: 0.40000001 | U13: 0.19981447 | V13: 0.0046804524 | W13: 0.13490763 | X13: 0.0049913395 | Y13: 0.17446367 | Z13: 0.16666666 | AA13: 0.28604379 | AB13: 0.0029693027 | AC13: 0.18854252 | AD13: 0.0058338051 | AE13: 0.24178453 | AF13: 0.3371731
A14: 2013 | B14: 0.21900651 | C14: 0.0022435295 | D14: 0.18724437 | E14: 0.0021225666 | F14: 0.20642577 | G14: 0.0022461708 | H14: 0.22667907 | I14: 0.002177062 | J14: 0.12335336 | K14: 0.0015931069 | L14: 0.037290908 | M14: 0.001088346 | O14: 0.30312014 | P14: 0.003925065 | Q14: 0.2 | R14: 0.0049106013 | S14: 0.25441322 | T14: 0.37941629 | U14: 0.19062272 | V14: 0.0043267617 | W14: 0.13333334 | X14: 0.0042694448 | Y14: 0.15810482 | Z14: 0.14381272 | AA14: 0.27700573 | AB14: 0.0035030125 | AC14: 0.16666667 | AD14: 0.0026077305 | AE14: 0.2403204 | AF14: 0.30909091
A15: 2014 | B15: 0.1999113 | C15: 0.0022102366 | D15: 0.17209177 | E15: 0.001835288 | F15: 0.23376784 | G15: 0.0019954119 | H15: 0.23761182 | I15: 0.0018866325 | J15: 0.11716729 | K15: 0.0013782706 | L15: 0.039450016 | M15: 0.00098384742 | O15: 0.28667441 | P15: 0.0035018602 | Q15: 0.18055555 | R15: 0.0060818852 | S15: 0.2359574 | T15: 0.34099379 | U15: 0.19306996 | V15: 0.0043935524 | W15: 0.13432837 | X15: 0.0042885491 | Y15: 0.16130146 | Z15: 0.16666666 | AA15: 0.26309657 | AB15: 0.0020672779 | AC15: 0.16666667 | AD15: 0 | AE15: 0.22327457 | AF15: 0.26857811
A16: 2015 | B16: 0.19043978 | C16: 0.0020544888 | D16: 0.16591096 | E16: 0.001916977 | F16: 0.24269326 | G16: 0.0019386346 | H16: 0.24960393 | I16: 0.0021846734 | J16: 0.11444961 | K16: 0.001686597 | L16: 0.036902487 | M16: 0.0009873251 | O16: 0.27616078 | P16: 0.0032199288 | Q16: 0.1724138 | R16: 0.0054024649 | S16: 0.23218717 | T16: 0.31106579 | U16: 0.18530856 | V16: 0.0040611527 | W16: 0.13043478 | X16: 0.0026594296 | Y16: 0.15376756 | Z16: 0.15036637 | AA16: 0.25400931 | AB16: 0.0027657168 | AC16: 0.16666667 | AD16: 0.00168556 | AE16: 0.21919821 | AF16: 0.24242425
... A19: 2018 | B19: 0.16723521 | C19: 0.0018851288 | D19: 0.15468165 | E19: 0.0015482137 | F19: 0.2958819 | G19: 0.0022992603 | H19: 0.26212373 | I19: 0.0018917717 | J19: 0.090440191 | K19: 0.0015119751 | L19: 0.029637311 | M19: 0.00096276187 | O19: 0.25812891 | P19: 0.0039048011 | Q19: 0.16666667 | R19: 0.0018351546 | S19: 0.2211038 | T19: 0.24242425 | U19: 0.18788972 | V19: 0.0049738018 | W19: 0.13043478 | X19: 0.0043555032 | Y19: 0.1572797 | Z19: 0.14381272 | AA19: 0.2407926 | AB19: 0.0031645854 | AC19: 0.15789473 | AD19: 0.0039652162 | AE19: 0.20937192 | AF19: 0.23785803

Sheet Old Share by Employment
B2: Ope | D2: Agr | F2: Rural | H2: Urban | J2: A+R | L2: A+N | N2: Some Rural | P2: Some Urban | R2: Ope+Agr | T2: Pop | W2: Some Agr | X2: Part-time
A3: 2003
A4: 2004 | B4: 0.58327407 | C4: 0.00443717 | D4: 0.51027226 | E4: 0.0052978648 | F4: 0.30534688 | G4: 0.0056571029 | H4: 0.083710738 | I4: 0.0032298213 | J4: 0.42635977 | K4: 0.005272991 | L4: 0.17785844 | M4: 0.0074126711 | N4: 0.36804372 | O4: 0.0040741242 | P4: 0.10778829 | Q4: 0.0027370299 | R4: 0.55126041 | S4: 0.0037293984 | T4: 0.40526178 | U4: 0.002519577 | W4: =(B4*'Employment Share'!B5+'Old Share by Employment'!D4*'Employment Share'!D5+'Old Share by Employment'!J4*'Employment Share'!J5+'Old Share by Employment'!L4*'Employment Share'!L5)/('Employment Share'!B5+'Employment Share'!D5+'Employment Share'!J5+'Employment Share'!L5) -> 0.49711255 | X4: =(J4*'Employment Share'!J5+'Old Share by Employment'!L4*'Employment Share'!L5)/('Employment Share'!J5+'Employment Share'!L5) -> 0.36872567
A5: 2005 | B5: 0.58705598 | C5: 0.0038216216 | D5: 0.51949584 | E5: 0.0046263752 | F5: 0.31010503 | G5: 0.0053230068 | H5: 0.084919475 | I5: 0.0028697958 | J5: 0.4316414 | K5: 0.0056939237 | L5: 0.19217081 | M5: 0.0073096016 | N5: 0.37311187 | O5: 0.0041531478 | P5: 0.1123506 | Q5: 0.0032584586 | R5: 0.55757499 | S5: 0.0035737739 | T5: 0.40805089 | U5: 0.0024191942 | W5: =(B5*'Employment Share'!B6+'Old Share by Employment'!D5*'Employment Share'!D6+'Old Share by Employment'!J5*'Employment Share'!J6+'Old Share by Employment'!L5*'Employment Share'!L6)/('Employment Share'!B6+'Employment Share'!D6+'Employment Share'!J6+'Employment Share'!L6) -> 0.50391156 | X5: =(J5*'Employment Share'!J6+'Old Share by Employment'!L5*'Employment Share'!L6)/('Employment Share'!J6+'Employment Share'!L6) -> 0.37689413
A6: 2006 | B6: 0.60638034 | C6: 0.0044676876 | D6: 0.53910524 | E6: 0.0044633239 | F6: 0.30323905 | G6: 0.0055903615 | H6: 0.096415639 | I6: 0.0032326591 | J6: 0.43828058 | K6: 0.006585828 | L6: 0.22354558 | M6: 0.009040921 | N6: 0.37107009 | O6: 0.0043507144 | P6: 0.12583604 | Q6: 0.0033910258 | R6: 0.57714897 | S6: 0.0030446695 | T6: 0.41170797 | U6: 0.0021506718 | W6: =(B6*'Employment Share'!B7+'Old Share by Employment'!D6*'Employment Share'!D7+'Old Share by Employment'!J6*'Employment Share'!J7+'Old Share by Employment'!L6*'Employment Share'!L7)/('Employment Share'!B7+'Employment Share'!D7+'Employment Share'!J7+'Employment Share'!L7) -> 0.52052685 | X6: =(J6*'Employment Share'!J7+'Old Share by Employment'!L6*'Employment Share'!L7)/('Employment Share'!J7+'Employment Share'!L7) -> 0.3865917
A7: 2007 | B7: 0.62997526 | C7: 0.0045454674 | D7: 0.55753869 | E7: 0.0061081732 | F7: 0.31143317 | G7: 0.0057652681 | H7: 0.10676478 | I7: 0.0032692892 | J7: 0.47092932 | K7: 0.0058001131 | L7: 0.23832685 | M7: 0.010837584 | N7: 0.39226431 | O7: 0.0042265975 | P7: 0.13579884 | Q7: 0.0034743696 | R7: 0.59862804 | S7: 0.003599213 | T7: 0.42128441 | U7: 0.0023563213 | W7: =(B7*'Employment Share'!B8+'Old Share by Employment'!D7*'Employment Share'!D8+'Old Share by Employment'!J7*'Employment Share'!J8+'Old Share by Employment'!L7*'Employment Share'!L8)/('Employment Share'!B8+'Employment Share'!D8+'Employment Share'!J8+'Employment Share'!L8) -> 0.54090758 | X7: =(J7*'Employment Share'!J8+'Old Share by Employment'!L7*'Employment Share'!L8)/('Employment Share'!J8+'Employment Share'!L8) -> 0.41424677
A8: 2008 | B8: 0.65814066 | C8: 0.0042362376 | D8: 0.57283258 | E8: 0.0062946379 | F8: 0.32314283 | G8: 0.0056479592 | H8: 0.1242924 | I8: 0.0035859791 | J8: 0.48665467 | K8: 0.0057600192 | L8: 0.27658486 | M8: 0.0091644628 | N8: 0.40068334 | O8: 0.004207476 | P8: 0.15448871 | Q8: 0.0034731484 | R8: 0.62005013 | S8: 0.0032186888 | T8: 0.43921292 | U8: 0.0021241696 | W8: =(B8*'Employment Share'!B9+'Old Share by Employment'!D8*'Employment Share'!D9+'Old Share by Employment'!J8*'Employment Share'!J9+'Old Share by Employment'!L8*'Employment Share'!L9)/('Employment Share'!B9+'Employment Share'!D9+'Employment Share'!J9+'Employment Share'!L9) -> 0.56541079 | X8: =(J8*'Employment Share'!J9+'Old Share by Employment'!L8*'Employment Share'!L9)/('Employment Share'!J9+'Employment Share'!L9) -> 0.43569392
A9: 2009 | B9: 0.68305409 | C9: 0.004942894 | D9: 0.57866883 | E9: 0.0053985976 | F9: 0.33659765 | G9: 0.0053663584 | H9: 0.12236437 | I9: 0.0041447668 | J9: 0.48896995 | K9: 0.0068644281 | L9: 0.24700513 | M9: 0.010937186 | N9: 0.40457186 | O9: 0.0041166954 | P9: 0.14468691 | Q9: 0.0031592739 | R9: 0.6349954 | S9: 0.0033017467 | T9: 0.44076249 | U9: 0.0025066952 | W9: =(B9*'Employment Share'!B10+'Old Share by Employment'!D9*'Employment Share'!D10+'Old Share by Employment'!J9*'Employment Share'!J10+'Old Share by Employment'!L9*'Employment Share'!L10)/('Employment Share'!B10+'Employment Share'!D10+'Employment Share'!J10+'Employment Share'!L10) -> 0.57645972 | X9: =(J9*'Employment Share'!J10+'Old Share by Employment'!L9*'Employment Share'!L10)/('Employment Share'!J10+'Employment Share'!L10) -> 0.43249001
A10: 2010 | B10: 0.70427722 | C10: 0.0051216637 | D10: 0.59099579 | E10: 0.0061065801 | F10: 0.33869389 | G10: 0.0058624228 | H10: 0.1376636 | I10: 0.0039106784 | J10: 0.51716942 | K10: 0.0073643359 | L10: 0.26911315 | M10: 0.010312089 | N10: 0.41442603 | O10: 0.0042257421 | P10: 0.1599687 | Q10: 0.0034643477 | R10: 0.65218157 | S10: 0.0034230107 | T10: 0.45122904 | U10: 0.0026245282 | W10: =(B10*'Employment Share'!B11+'Old Share by Employment'!D10*'Employment Share'!D11+'Old Share by Employment'!J10*'Employment Share'!J11+'Old Share by Employment'!L10*'Employment Share'!L11)/('Employment Share'!B11+'Employment Share'!D11+'Employment Share'!J11+'Employment Share'!L11) -> 0.59644226 | X10: =(J10*'Employment Share'!J11+'Old Share by Employment'!L10*'Employment Share'!L11)/('Employment Share'!J11+'Employment Share'!L11) -> 0.45844193
A11: 2011 | B11: 0.72100347 | C11: 0.0056223418 | D11: 0.5988372 | E11: 0.006113641 | F11: 0.33707541 | G11: 0.0061553819 | H11: 0.15165938 | I11: 0.0042216838 | J11: 0.53180915 | K11: 0.007179623 | L11: 0.30246502 | M11: 0.01290119 | N11: 0.41885123 | O11: 0.0050735334 | P11: 0.17616418 | Q11: 0.0043038023 | R11: 0.66512603 | S11: 0.0038344576 | T11: 0.46059778 | U11: 0.0021629962 | W11: =(B11*'Employment Share'!B12+'Old Share by Employment'!D11*'Employment Share'!D12+'Old Share by Employment'!J11*'Employment Share'!J12+'Old Share by Employment'!L11*'Employment Share'!L12)/('Employment Share'!B12+'Employment Share'!D12+'Employment Share'!J12+'Employment Share'!L12) -> 0.61070547 | X11: =(J11*'Employment Share'!J12+'Old Share by Employment'!L11*'Employment Share'!L12)/('Employment Share'!J12+'Employment Share'!L12) -> 0.47909969
A12: 2012 | B12: 0.72621644 | C12: 0.0050113979 | D12: 0.61702436 | E12: 0.0059277657 | F12: 0.35041013 | G12: 0.0056984951 | H12: 0.16066264 | I12: 0.0045894044 | J12: 0.55248618 | K12: 0.0066070035 | L12: 0.30240792 | M12: 0.012525968 | N12: 0.43200344 | O12: 0.0052589732 | P12: 0.18390805 | Q12: 0.0038371861 | R12: 0.67635643 | S12: 0.0037641074 | T12: 0.47018424 | U12: 0.0026668396 | W12: =(B12*'Employment Share'!B13+'Old Share by Employment'!D12*'Employment Share'!D13+'Old Share by Employment'!J12*'Employment Share'!J13+'Old Share by Employment'!L12*'Employment Share'!L13)/('Employment Share'!B13+'Employment Share'!D13+'Employment Share'!J13+'Employment Share'!L13) -> 0.62425551 | X12: =(J12*'Employment Share'!J13+'Old Share by Employment'!L12*'Employment Share'!L13)/('Employment Share'!J13+'Employment Share'!L13) -> 0.49476953
A13: 2013 | B13: 0.75450796 | C13: 0.0051426403 | D13: 0.63663757 | E13: 0.0054525491 | F13: 0.36690351 | G13: 0.0059796507 | H13: 0.17244513 | I13: 0.0040848977 | J13: 0.56917447 | K13: 0.0072384109 | L13: 0.33509833 | M13: 0.013497418 | N13: 0.44256267 | O13: 0.0046102456 | P13: 0.19651635 | Q13: 0.0038323277 | R13: 0.70018053 | S13: 0.0037465936 | T13: 0.48227131 | U13: 0.0026426262 | W13: =(B13*'Employment Share'!B14+'Old Share by Employment'!D13*'Employment Share'!D14+'Old Share by Employment'!J13*'Employment Share'!J14+'Old Share by Employment'!L13*'Employment Share'!L14)/('Employment Share'!B14+'Employment Share'!D14+'Employment Share'!J14+'Employment Share'!L14) -> 0.64765885 | X13: =(J13*'Employment Share'!J14+'Old Share by Employment'!L13*'Employment Share'!L14)/('Employment Share'!J14+'Employment Share'!L14) -> 0.51483757
A14: 2014 | B14: 0.75390315 | C14: 0.0053765406 | D14: 0.64152962 | E14: 0.0058544711 | F14: 0.37750739 | G14: 0.0061333929 | H14: 0.19063728 | I14: 0.0044810162 | J14: 0.59120458 | K14: 0.0063465014 | L14: 0.34171778 | M14: 0.010656568 | N14: 0.45537519 | O14: 0.0032915585 | P14: 0.21466857 | Q14: 0.0037874486 | R14: 0.70260042 | S14: 0.00392729 | T14: 0.48770541 | U14: 0.0025310698 | W14: =(B14*'Employment Share'!B15+'Old Share by Employment'!D14*'Employment Share'!D15+'Old Share by Employment'!J14*'Employment Share'!J15+'Old Share by Employment'!L14*'Employment Share'!L15)/('Employment Share'!B15+'Employment Share'!D15+'Employment Share'!J15+'Employment Share'!L15) -> 0.6504977 | X14: =(J14*'Employment Share'!J15+'Old Share by Employment'!L14*'Employment Share'!L15)/('Employment Share'!J15+'Employment Share'!L15) -> 0.52836186
A15: 2015 | B15: 0.77407891 | C15: 0.0041619842 | D15: 0.65315884 | E15: 0.0048067984 | F15: 0.38906682 | G15: 0.0048244041 | H15: 0.19289453 | I15: 0.0044940151 | J15: 0.62252885 | K15: 0.0065982686 | L15: 0.35131663 | M15: 0.01208501 | N15: 0.47056288 | O15: 0.0041692881 | P15: 0.21759766 | Q15: 0.0039784396 | R15: 0.71880627 | S15: 0.0035878518 | T15: 0.49748856 | U15: 0.0026330035 | W15: =(B15*'Employment Share'!B16+'Old Share by Employment'!D15*'Employment Share'!D16+'Old Share by Employment'!J15*'Employment Share'!J16+'Old Share by Employment'!L15*'Employment Share'!L16)/('Employment Share'!B16+'Employment Share'!D16+'Employment Share'!J16+'Employment Share'!L16) -> 0.66967179 | X15: =(J15*'Employment Share'!J16+'Old Share by Employment'!L15*'Employment Share'!L16)/('Employment Share'!J16+'Employment Share'!L16) -> 0.55640221
... A18: 2018 | B18: 0.80709726 | C18: 0.0053542806 | D18: 0.71238393 | E18: 0.005431456 | F18: 0.43433368 | G18: 0.0053770076 | H18: 0.24400407 | I18: 0.0046693049 | J18: 0.66504329 | K18: 0.0076733134 | L18: 0.4517974 | M18: 0.012710506 | N18: 0.49498543 | O18: 0.0036166145 | P18: 0.26801205 | Q18: 0.0038599882 | R18: 0.76179194 | S18: 0.0038037719 | T18: 0.52171785 | U18: 0.0024456747 | W18: =(B18*'Employment Share'!B19+'Old Share by Employment'!D18*'Employment Share'!D19+'Old Share by Employment'!J18*'Employment Share'!J19+'Old Share by Employment'!L18*'Employment Share'!L19)/('Employment Share'!B19+'Employment Share'!D19+'Employment Share'!J19+'Employment Share'!L19) -> 0.72106011 | X18: =(J18*'Employment Share'!J19+'Old Share by Employment'!L18*'Employment Share'!L19)/('Employment Share'!J19+'Employment Share'!L19) -> 0.61241033
A19: 2019 | B19: 0.81721145 | C19: 0.003930721 | D19: 0.73664552 | E19: 0.0051660822 | F19: 0.45491883 | G19: 0.0044962922 | H19: 0.26113093 | I19: 0.0038997794 | J19: 0.67942125 | K19: 0.0069431993 | L19: 0.49899599 | M19: 0.016691569 | N19: 0.50727355 | O19: 0.0038607509 | P19: 0.28519261 | Q19: 0.0049147354 | R19: 0.77920705 | S19: 0.0038390823 | T19: 0.5256173 | U19: 0.0027994975
A20: 2020 | B20: 0.82278067 | C20: 0.0057215192 | D20: 0.74858856 | E20: 0.0065321084 | F20: 0.46310642 | G20: 0.0042115254 | H20: 0.27542955 | I20: 0.0041960808 | J20: 0.70066386 | K20: 0.0067660939 | L20: 0.45027626 | M20: 0.014142344 | N20: 0.51871997 | O20: 0.0036861817 | P20: 0.2950145 | Q20: 0.0040644137 | R20: 0.78713125 | S20: 0.0038185765 | T20: 0.53985757 | U20: 0.0024599659

Sheet Employment Old
B2: Ope | D2: Agr | F2: Rural | H2: Urban | J2: A+R | L2: A+N | N2: Some Rural | P2: Some Urban | R2: Ope+Agr | T2: Pop
A3: 2003
A4: 2004 | B4: 0.39654988 | C4: 0.0041264328 | D4: 0.27095872 | E4: 0.0032915187 | F4: 0.1114037 | G4: 0.0023017295 | H4: 0.030793207 | I4: 0.0014445318 | J4: 0.16723989 | K4: 0.0032915187 | L4: 0.021066207 | M4: 0.0011904018 | N4: 0.27864361 | O4: 0.0031419906 | P4: 0.053847808 | Q4: 0.0016081786 | R4: 0.6675086 | S4: 0.0033465363 | T4: 0.40526178 | U4: 0.0022652289
A5: 2005 | B5: 0.39363116 | C5: 0.0034346764 | D5: 0.26967901 | E5: 0.0032381571 | F5: 0.11168472 | G5: 0.002020448 | H5: 0.032610919 | I5: 0.0012191335 | J5: 0.16734819 | K5: 0.0032381571 | L5: 0.022081373 | M5: 0.0011051834 | N5: 0.27903292 | O5: 0.0031082686 | P5: 0.057656921 | Q5: 0.0016065624 | R5: 0.66331017 | S5: 0.0032654493 | T5: 0.40805089 | U5: 0.0020559537
A6: 2006 | B6: 0.39158905 | C6: 0.0035931859 | D6: 0.26750067 | E6: 0.0032618272 | F6: 0.11014107 | G6: 0.0022443051 | H6: 0.04109662 | I6: 0.0015250999 | J6: 0.1606601 | K6: 0.0032618272 | L6: 0.025978174 | M6: 0.0011849164 | N6: 0.27080116 | O6: 0.0033978648 | P6: 0.070109129 | Q6: 0.0019313986 | R6: 0.65908968 | S6: 0.0032129341 | T6: 0.41170797 | U6: 0.0025103951
A7: 2007 | B7: 0.3800115 | C7: 0.0036194201 | D7: 0.25657669 | E7: 0.0035796023 | F7: 0.11108559 | G7: 0.0022212837 | H7: 0.047501437 | I7: 0.0015402131 | J7: 0.17260195 | K7: 0.0035796023 | L7: 0.028144745 | M7: 0.0012353959 | N7: 0.28368753 | O7: 0.0033296729 | P7: 0.079724297 | Q7: 0.0017972433 | R7: 0.63658816 | S7: 0.0036569014 | T7: 0.42128441 | U7: 0.0023521318
A8: 2008 | B8: 0.37412813 | C8: 0.003370452 | D8: 0.26268914 | E8: 0.0035671543 | F8: 0.11739457 | G8: 0.0023028997 | H8: 0.054190364 | I8: 0.0016454591 | J8: 0.15945917 | K8: 0.0035671543 | L8: 0.029026719 | M8: 0.0011955663 | N8: 0.27685374 | O8: 0.0030202719 | P8: 0.086329006 | Q8: 0.0021839286 | R8: 0.63681728 | S8: 0.0035782428 | T8: 0.43921292 | U8: 0.0026204321
A9: 2009 | B9: 0.36849797 | C9: 0.0040462241 | D9: 0.26635996 | E9: 0.0032030127 | F9: 0.13023004 | G9: 0.0024707546 | H9: 0.055913396 | I9: 0.0016309695 | J9: 0.15236807 | K9: 0.0032030127 | L9: 0.023437077 | M9: 0.0010810866 | N9: 0.28259811 | O9: 0.0030938706 | P9: 0.082543977 | Q9: 0.0019049166 | R9: 0.63485789 | S9: 0.0034591691 | T9: 0.44076249 | U9: 0.0024818152
A10: 2010 | B10: 0.36264288 | C10: 0.003357488 | D10: 0.25910231 | E10: 0.0034640464 | F10: 0.13504322 | G10: 0.0024039946 | H10: 0.063339837 | I10: 0.0018855262 | J10: 0.1519933 | K10: 0.0034640464 | L10: 0.024533035 | M10: 0.0011116891 | N10: 0.28703651 | O10: 0.0033233897 | P10: 0.091218285 | Q10: 0.0022182234 | R10: 0.62174517 | S10: 0.0036207563 | T10: 0.45122904 | U10: 0.0022963563
A11: 2011 | B11: 0.35897288 | C11: 0.0037204917 | D11: 0.25132167 | E11: 0.0030603933 | F11: 0.13605995 | G11: 0.0023961412 | H11: 0.068494745 | I11: 0.0018491864 | J11: 0.1554058 | K11: 0.0030603933 | L11: 0.026375415 | M11: 0.0012262204 | N11: 0.29146576 | O11: 0.0031554594 | P11: 0.098239705 | Q11: 0.0024171034 | R11: 0.61029452 | S11: 0.0037964866 | T11: 0.46059778 | U11: 0.0025849773
A12: 2012 | B12: 0.35196808 | C12: 0.0034257926 | D12: 0.25130522 | E12: 0.003225686 | F12: 0.14284039 | G12: 0.0024707241 | H12: 0.071684167 | I12: 0.0020723089 | J12: 0.15251951 | K12: 0.003225686 | L12: 0.025048396 | M12: 0.001041717 | N12: 0.29535988 | O12: 0.0031663575 | P12: 0.10136681 | Q12: 0.0022238174 | R12: 0.60327333 | S12: 0.0040028417 | T12: 0.47018424 | U12: 0.00247021
A13: 2013 | B13: 0.34263322 | C13: 0.0038350448 | D13: 0.24717787 | E13: 0.0030261222 | F13: 0.1570451 | G13: 0.0029344584 | H13: 0.077674448 | I13: 0.0018509204 | J13: 0.1455811 | K13: 0.0030261222 | L13: 0.025910979 | M13: 0.0013117206 | N13: 0.30262619 | O13: 0.0039192671 | P13: 0.10756273 | Q13: 0.0026105577 | R13: 0.58981109 | S13: 0.0039719329 | T13: 0.48227131 | U13: 0.0028210082
A14: 2014 | B14: 0.32823122 | C14: 0.0035506317 | D14: 0.23463251 | E14: 0.0026700955 | F14: 0.16841899 | G14: 0.0026433915 | H14: 0.085432053 | I14: 0.0019110633 | J14: 0.15120544 | K14: 0.0026700955 | L14: 0.027238496 | M14: 0.0010705214 | N14: 0.31962442 | O14: 0.0033915245 | P14: 0.11751186 | Q14: 0.0029005085 | R14: 0.56286371 | S14: 0.0037144988 | T14: 0.48770541 | U14: 0.002331486
A15: 2015 | B15: 0.32497761 | C15: 0.0031935356 | D15: 0.23087636 | E15: 0.0030050743 | F15: 0.17522132 | G15: 0.0030478192 | H15: 0.086143441 | I15: 0.0024754442 | J15: 0.15035313 | K15: 0.0030050743 | L15: 0.02720581 | M15: 0.00111372 | N15: 0.32557446 | O15: 0.0036816197 | P15: 0.11857157 | Q15: 0.0022337795 | R15: 0.55585396 | S15: 0.0031761737 | T15: 0.49748856 | U15: 0.0022085793
... A20: 2020 | B20: 0.25487816 | C20: 0.0030996241 | D20: 0.21448793 | E20: 0.0030069815 | F20: 0.2538166 | G20: 0.0033184672 | H20: 0.13208978 | I20: 0.0022675651 | J20: 0.11737943 | K20: 0.0030069815 | L20: 0.024719441 | M20: 0.00095168367 | N20: 0.37119603 | O20: 0.0032703269 | P20: 0.15943788 | Q20: 0.0028245121 | R20: 0.4693661 | S20: 0.0029275406 | T20: 0.53985757 | U20: 0.0028612765

Sheet Employment Young
B2: Ope | D2: Agr | F2: Rural | H2: Urban | J2: A+R | L2: A+N | N2: Some Rural | P2: Some Urban | R2: Ope+Agr | T2: Pop
A3: 2003
A4: 2004 | B4: 0.19305699 | C4: 0.0024063322 | D4: 0.17720082 | E4: 0.0021896898 | F4: 0.17269665 | G4: 0.0022059225 | H4: 0.22967629 | I4: 0.0028159267 | J4: 0.15332504 | K4: 0.0022488036 | L4: 0.066354185 | M4: 0.0014083298 | N4: 0.32602167 | O4: 0.003016778 | P4: 0.30372053 | Q4: 0.0027142775 | R4: 0.37025779 | S4: 0.0030331253 | T4: 0.59473825 | U4: 0.0022711377
A5: 2005 | B5: 0.19086713 | C5: 0.0026894286 | D5: 0.17194602 | E5: 0.0022529522 | F5: 0.17127655 | G5: 0.0021226467 | H5: 0.24223952 | I5: 0.0021907589 | J5: 0.1518974 | K5: 0.0022034585 | L5: 0.063986473 | M5: 0.0014731868 | N5: 0.32317394 | O5: 0.0026304496 | P5: 0.31401289 | Q5: 0.0026354021 | R5: 0.36281314 | S5: 0.0028653971 | T5: 0.59194911 | U5: 0.002014623
A6: 2006 | B6: 0.17789285 | C6: 0.0023937651 | D6: 0.16004768 | E6: 0.0020209716 | F6: 0.17711049 | G6: 0.0025020002 | H6: 0.26954028 | I6: 0.0029701805 | J6: 0.14410253 | K6: 0.0020543998 | L6: 0.063147306 | M6: 0.0014774041 | N6: 0.32121304 | O6: 0.0026459231 | P6: 0.34084645 | Q6: 0.002849231 | R6: 0.33794054 | S6: 0.0029822809 | T6: 0.588292 | U6: 0.0023807178
A7: 2007 | B7: 0.16248536 | C7: 0.0025350642 | D7: 0.14822713 | E7: 0.0026013039 | F7: 0.17879245 | G7: 0.0025422566 | H7: 0.28930423 | I7: 0.0029513647 | J7: 0.14116073 | K7: 0.0021489954 | L7: 0.065479174 | M7: 0.0015980736 | N7: 0.31995317 | O7: 0.003130923 | P7: 0.36933434 | Q7: 0.0027440533 | R7: 0.31071249 | S7: 0.0030727864 | T7: 0.57871556 | U7: 0.0025014537
A8: 2008 | B8: 0.15220407 | C8: 0.0022010095 | D8: 0.1534227 | E8: 0.0022509249 | F8: 0.1925873 | G8: 0.0024737024 | H8: 0.29902929 | I8: 0.0029517869 | J8: 0.13173929 | K8: 0.0021754908 | L8: 0.059461277 | M8: 0.0016415624 | N8: 0.3243266 | O8: 0.0030623081 | P8: 0.37004665 | Q8: 0.0028468138 | R8: 0.30562675 | S8: 0.0030994713 | T8: 0.56078708 | U8: 0.0029253161
A9: 2009 | B9: 0.13476388 | C9: 0.0021057969 | D9: 0.15285183 | E9: 0.0022823182 | F9: 0.20229512 | G9: 0.0028436237 | H9: 0.31607014 | I9: 0.0030618538 | J9: 0.12550659 | K9: 0.0019167879 | L9: 0.056311592 | M9: 0.0017549982 | N9: 0.3278017 | O9: 0.002848034 | P9: 0.38458258 | Q9: 0.0028723499 | R9: 0.28761572 | S9: 0.0032853684 | T9: 0.55923754 | U9: 0.0027065335
A10: 2010 | B10: 0.12520631 | C10: 0.002157164 | D10: 0.14744177 | E10: 0.0024965866 | F10: 0.21680726 | G10: 0.0030260971 | H10: 0.32624245 | I10: 0.0032534339 | J10: 0.11667889 | K10: 0.0024671655 | L10: 0.054786354 | M10: 0.0013934835 | N10: 0.33348614 | O10: 0.0033089041 | P10: 0.39386576 | Q10: 0.0031598336 | R10: 0.2726481 | S10: 0.0029877771 | T10: 0.54877096 | U10: 0.0024502785
A11: 2011 | B11: 0.11861296 | C11: 0.0023487553 | D11: 0.14376426 | E11: 0.002032626 | F11: 0.2284949 | G11: 0.003007825 | H11: 0.3271654 | I11: 0.0033815417 | J11: 0.11682706 | K11: 0.0020438589 | L11: 0.051939677 | M11: 0.0014225196 | N11: 0.34532195 | O11: 0.0031721501 | P11: 0.39230081 | Q11: 0.0034046809 | R11: 0.26237723 | S11: 0.0029913839 | T11: 0.53940219 | U11: 0.0024214895
A12: 2012 | B12: 0.1177573 | C12: 0.0023221932 | D12: 0.13842469 | E12: 0.0022951155 | F12: 0.23499401 | G12: 0.0029465572 | H12: 0.3323442 | I12: 0.0032777207 | J12: 0.10963611 | K12: 0.0024221928 | L12: 0.051278047 | M12: 0.0014597425 | N12: 0.34463012 | O12: 0.0033503792 | P12: 0.39918789 | Q12: 0.0038897607 | R12: 0.25618199 | S12: 0.0029273694 | T12: 0.52981573 | U12: 0.0026089752
A13: 2013 | B13: 0.10384657 | C13: 0.0022947139 | D13: 0.1314155 | E13: 0.0025231193 | F13: 0.25242454 | G13: 0.003059983 | H13: 0.34722677 | I13: 0.0035998507 | J13: 0.10264792 | K13: 0.0021145868 | L13: 0.047891468 | M13: 0.0014014889 | N13: 0.35507247 | O13: 0.0033951143 | P13: 0.40966547 | Q13: 0.0038607705 | R13: 0.23526207 | S13: 0.0030400092 | T13: 0.51772869 | U13: 0.0029035972
A14: 2014 | B14: 0.10200186 | C14: 0.0018960717 | D14: 0.12481378 | E14: 0.0023007023 | F14: 0.26438546 | G14: 0.0032480687 | H14: 0.34529796 | I14: 0.0036987499 | J14: 0.099534452 | K14: 0.0019977742 | L14: 0.049953446 | M14: 0.0013508881 | N14: 0.36391991 | O14: 0.0033543902 | P14: 0.40926445 | Q14: 0.0035761124 | R14: 0.22681564 | S14: 0.0033443507 | T14: 0.51229459 | U14: 0.0025398361
A15: 2015 | B15: 0.093899257 | C15: 0.0019063209 | D15: 0.12137476 | E15: 0.0022007527 | F15: 0.27239156 | G15: 0.0029517761 | H15: 0.35683689 | I15: 0.003006056 | J15: 0.090255551 | K15: 0.0020219241 | L15: 0.049731646 | M15: 0.0016667853 | N15: 0.36264712 | O15: 0.0027896799 | P15: 0.42207888 | Q15: 0.0035730002 | R15: 0.21527402 | S15: 0.0035257668 | T15: 0.50251144 | U15: 0.0027729329
... A20: 2020 | B20: 0.064408988 | C20: 0.0016518509 | D20: 0.084514558 | E20: 0.0020876196 | F20: 0.34523457 | G20: 0.0038468058 | H20: 0.40768638 | I20: 0.0037485962 | J20: 0.058833994 | K20: 0.0015313671 | L20: 0.035407152 | M20: 0.0013299807 | N20: 0.40406856 | O20: 0.0034704849 | P20: 0.44700789 | Q20: 0.0042905575 | R20: 0.14892355 | S20: 0.0027553525 | T20: 0.46014246 | U20: 0.0026192183

Sheet Income Moments
C1: Rural Nonagr | J1: Urban Nonagr | Q1: Nonagr | Y1: Wage Differentials | AF1: Rural-Urban | AK1: Farming-Rural | AP1: Farming-Nonagr | AU1: Wage-Diff: W-WO Operator | AZ1: Wage Differentials | BE1: Farming-Nonagr: Switchers
C2: Disp | E2: Corr | G2: Spearman | J2: Disp | L2: Corr | N2: Spearman | Q2: Disp | S2: Corr | U2: Spearman | Y2: U-R | AA2: R-A | AC2: R-F | AF2: Corr | AH2: Spearman | AK2: Corr | AM2: Spearman | AP2: Corr | AR2: Spearman | AU2: Median | AW2: Mean | AZ2: N-A | BB2: N-F | BE2: Corr | BG2: Spearman
B4: 2004 | C4: 0.61298686 | D4: 0.005953555 | E4: 0.55144751 | F4: 0.035354219 | G4: 0.49547714 | H4: 0.028830625 | J4: 0.60349464 | K4: 0.0052348017 | L4: 0.62842196 | M4: 0.020595606 | N4: 0.64469713 | O4: 0.017053032 | Q4: 0.60972589 | R4: 0.004386601 | S4: 0.58333784 | T4: 0.018134808 | U4: 0.5580619 | V4: 0.01483996 | Y4: -0.15451121 | Z4: 0.010545364 | AA4: 0.46583933 | AB4: 0.0088654226 | AC4: 0.46123543 | AD4: 0.011435928 | AF4: 0.37982029 | AG4: 0.052384134 | AH4: 0.34037039 | AI4: 0.04660945 | AK4: 0.045192476 | AL4: 0.028177405 | AM4: 0.067263819 | AN4: 0.021922961 | AP4: 0.082156852 | AQ4: 0.017370988 | AR4: 0.079620935 | AS4: 0.0144145 | AU4: -0.20203853 | AV4: 0.018351631 | AW4: -0.28062466 | AX4: 0.012887942 | AZ4: 0.37233943 | BA4: 0.0051888665 | BB4: 0.36773556 | BC4: 0.0089502539 | BE4: 0.11210585 | BF4: 0.037688147 | BG4: 0.13188796 | BH4: 0.037606552
B5: 2005 | C5: 0.56002563 | D5: 0.0058143185 | E5: 0.4824177 | F5: 0.032502156 | G5: 0.47113734 | H5: 0.020052517 | J5: 0.58179611 | K5: 0.0049220934 | L5: 0.60194528 | M5: 0.02822227 | N5: 0.61155599 | O5: 0.020515151 | Q5: 0.57383418 | R5: 0.0038875004 | S5: 0.50281298 | T5: 0.020017276 | U5: 0.51495928 | V5: 0.016109625 | Y5: -0.12439119 | Z5: 0.0094356304 | AA5: 0.48025584 | AB5: 0.0073124086 | AC5: 0.58106905 | AD5: 0.0099013541 | AF5: 0.22894992 | AG5: 0.050331395 | AH5: 0.26084536 | AI5: 0.04344558 | AK5: 0.12688732 | AL5: 0.022957725 | AM5: 0.11510488 | AN5: 0.019884154 | AP5: 0.081422463 | AQ5: 0.01537752 | AR5: 0.072594576 | AS5: 0.016156845 | AU5: -0.19929457 | AV5: 0.016538322 | AW5: -0.22810534 | AX5: 0.012784203 | AZ5: 0.40704662 | BA5: 0.0041533965 | BB5: 0.50785983 | BC5: 0.0088008782 | BE5: 0.085043482 | BF5: 0.035265796 | BG5: 0.11812521 | BH5: 0.040041935
B6: 2006 | C6: 0.56808972 | D6: 0.0057030823 | E6: 0.46080008 | F6: 0.03512321 | G6: 0.43563727 | H6: 0.029786807 | J6: 0.58005452 | K6: 0.0047503733 | L6: 0.60550141 | M6: 0.021836137 | N6: 0.62510252 | O6: 0.016442563 | Q6: 0.5807122 | R6: 0.0042103841 | S6: 0.4971768 | T6: 0.018464124 | U6: 0.5095731 | V6: 0.014465127 | Y6: -0.10526407 | Z6: 0.0093296561 | AA6: 0.40940014 | AB6: 0.0070141912 | AC6: 0.62719643 | AD6: 0.011140995 | AF6: 0.26330009 | AG6: 0.048441187 | AH6: 0.25468257 | AI6: 0.04996318 | AK6: 0.067635648 | AL6: 0.024308693 | AM6: 0.071399398 | AN6: 0.022316594 | AP6: 0.086036801 | AQ6: 0.017366648 | AR6: 0.073165901 | AS6: 0.017047068 | AU6: -0.12891459 | AV6: 0.012325751 | AW6: -0.18841377 | AX6: 0.012388832 | AZ6: 0.34449637 | BA6: 0.0047393721 | BB6: 0.56229264 | BC6: 0.0087953024 | BE6: 0.19501555 | BF6: 0.037605025 | BG6: 0.2149504 | BH6: 0.035997666
B7: 2007 | C7: 0.54687029 | D7: 0.0066925744 | E7: 0.40325528 | F7: 0.03794739 | G7: 0.37096837 | H7: 0.030464027 | J7: 0.62608349 | K7: 0.0062956763 | L7: 0.64017856 | M7: 0.02336322 | N7: 0.6161651 | O7: 0.019411914 | Q7: 0.59758997 | R7: 0.0044251806 | S7: 0.5288744 | T7: 0.019099161 | U7: 0.4996793 | V7: 0.014274916 | Y7: -0.10654391 | Z7: 0.0090976274 | AA7: 0.32377639 | AB7: 0.0068199183 | AC7: 0.57056844 | AD7: 0.009512159 | AF7: 0.32848006 | AG7: 0.06315726 | AH7: 0.31218705 | AI7: 0.048523646 | AK7: 0.06493663 | AL7: 0.024106866 | AM7: 0.052934431 | AN7: 0.022698995 | AP7: 0.090052061 | AQ7: 0.014079531 | AR7: 0.077012293 | AS7: 0.015674077 | AU7: -0.1092155 | AV7: 0.013249722 | AW7: -0.18487221 | AX7: 0.011868523 | AZ7: 0.2576735 | BA7: 0.0055562914 | BB7: 0.50446552 | BC7: 0.0094168382 | BE7: 0.1992442 | BF7: 0.042186849 | BG7: 0.19349216 | BH7: 0.034616057
B8: 2008 | C8: 0.54970646 | D8: 0.0050488501 | E8: 0.38953683 | F8: 0.033145633 | G8: 0.37093028 | H8: 0.025640676 | J8: 0.59906828 | K8: 0.0052379733 | L8: 0.59753275 | M8: 0.023408102 | N8: 0.61152351 | O8: 0.017188843 | Q8: 0.58261108 | R8: 0.0039266329 | S8: 0.49293822 | T8: 0.016622528 | U8: 0.48495641 | V8: 0.015874723 | Y8: -0.10034055 | Z8: 0.0099146888 | AA8: 0.32322654 | AB8: 0.007489393 | AC8: 0.65976351 | AD8: 0.011733414 | AF8: 0.22541118 | AG8: 0.040392615 | AH8: 0.24372369 | AI8: 0.047078799 | AK8: 0.077675983 | AL8: 0.024995856 | AM8: 0.089371905 | AN8: 0.026424173 | AP8: 0.045508064 | AQ8: 0.018250611 | AR8: 0.07126195 | AS8: 0.018329868 | AU8: -0.074277401 | AV8: 0.013080888 | AW8: -0.15192367 | AX8: 0.011457063 | AZ8: 0.26009041 | BA8: 0.0043939971 | BB8: 0.59662735 | BC8: 0.011016403 | BE8: 0.095602125 | BF8: 0.0409564 | BG8: 0.0861049 | BH8: 0.042986501
B9: 2009 | C9: 0.58915186 | D9: 0.0090904329 | E9: 0.34523171 | F9: 0.058312055 | G9: 0.33944526 | H9: 0.038477264 | J9: 0.56524915 | K9: 0.004634094 | L9: 0.56707376 | M9: 0.02149885 | N9: 0.61151832 | O9: 0.015718486 | Q9: 0.5694176 | R9: 0.0039395764 | S9: 0.47472709 | T9: 0.023165274 | U9: 0.51301605 | V9: 0.014500316 | Y9: -0.058024056 | Z9: 0.011405749 | AA9: 0.46981475 | AB9: 0.010162573 | AC9: 0.72771668 | AD9: 0.013246158 | AF9: 0.27215949 | AG9: 0.049815122 | AH9: 0.2727749 | AI9: 0.049970079 | AK9: 0.079944484 | AL9: 0.030223522 | AM9: 0.10471042 | AN9: 0.03095546 | AP9: 0.085994884 | AQ9: 0.021457333 | AR9: 0.088674404 | AS9: 0.019545324 | AU9: -0.094356298 | AV9: 0.019312859 | AW9: -0.14200169 | AX9: 0.012882775 | AZ9: 0.42722023 | BA9: 0.0048362697 | BB9: 0.68512219 | BC9: 0.010336769 | BE9: 0.16801581 | BF9: 0.044517696 | BG9: 0.18465963 | BH9: 0.045035761
B10: 2010 | C10: 0.52300954 | D10: 0.0069113094 | E10: 0.4097296 | F10: 0.072806358 | G10: 0.3989377 | H10: 0.031669032 | J10: 0.565943 | K10: 0.0044236579 | L10: 0.58645821 | M10: 0.031927366 | N10: 0.61412853 | O10: 0.017448425 | Q10: 0.5531081 | R10: 0.0041035716 | S10: 0.5096457 | T10: 0.03293708 | U10: 0.52269185 | V10: 0.015586377 | Y10: -0.025604948 | Z10: 0.009419403 | AA10: 0.30406627 | AB10: 0.0080395369 | AC10: 0.62198246 | AD10: 0.013389801 | AF10: 0.23883674 | AG10: 0.06641116 | AH10: 0.24172437 | AI10: 0.056818999 | AK10: 0.12341671 | AL10: 0.02914479 | AM10: 0.10423164 | AN10: 0.029972507 | AP10: 0.085029952 | AQ10: 0.020034362 | AR10: 0.081845798 | AS10: 0.019587124 | AU10: -0.082276583 | AV10: 0.014955238 | AW10: -0.11810338 | AX10: 0.010770638 | AZ10: 0.28629625 | BA10: 0.0046662781 | BB10: 0.6042124 | BC10: 0.010557717 | BE10: 0.19937713 | BF10: 0.044500537 | BG10: 0.21519227 | BH10: 0.042630378
B11: 2011 | C11: 0.56928098 | D11: 0.0094513744 | E11: 0.39860025 | F11: 0.04928505 | G11: 0.38726899 | H11: 0.032658029 | J11: 0.56349844 | K11: 0.0051823366 | L11: 0.49200711 | M11: 0.027100431 | N11: 0.52887136 | O11: 0.020617314 | Q11: 0.56383908 | R11: 0.0039157877 | S11: 0.43733138 | T11: 0.023558458 | U11: 0.45694354 | V11: 0.019125011 | Y11: -0.026347976 | Z11: 0.010677028 | AA11: 0.29747245 | AB11: 0.0095285783 | AC11: 0.69341254 | AD11: 0.016954115 | AF11: 0.20293723 | AG11: 0.065786287 | AH11: 0.21984532 | AI11: 0.053266492 | AK11: 0.10147933 | AL11: 0.029414207 | AM11: 0.074074127 | AN11: 0.031455733 | AP11: 0.10650276 | AQ11: 0.019005161 | AR11: 0.10895483 | AS11: 0.017091839 | AU11: -0.045516491 | AV11: 0.016949797 | AW11: -0.070402987 | AX11: 0.013719274 | AZ11: 0.27941242 | BA11: 0.0050120903 | BB11: 0.67535251 | BC11: 0.011826331 | BE11: 0.12484337 | BF11: 0.083320044 | BG11: 0.19714284 | BH11: 0.052512273
B12: 2012 | C12: 0.54160482 | D12: 0.0078642638 | E12: 0.33494434 | F12: 0.046559975 | G12: 0.29985091 | H12: 0.037806258 | J12: 0.57223088 | K12: 0.0058980626 | L12: 0.52215385 | M12: 0.049730692 | N12: 0.54093903 | O12: 0.019896252 | Q12: 0.5618462 | R12: 0.003649571 | S12: 0.44341069 | T12: 0.044894841 | U12: 0.42927203 | V12: 0.018365655 | Y12: -0.0028685122 | Z12: 0.010588155 | AA12: 0.24447985 | AB12: 0.0083470391 | AC12: 0.78589743 | AD12: 0.016123654 | AF12: 0.1743632 | AG12: 0.064120851 | AH12: 0.17996167 | AI12: 0.053171769 | AK12: 0.12566029 | AL12: 0.031565405 | AM12: 0.13190237 | AN12: 0.035476882 | AP12: 0.11178192 | AQ12: 0.017882066 | AR12: 0.12173768 | AS12: 0.02173844 | AU12: -0.048789978 | AV12: 0.010985081 | AW12: -0.065872043 | AX12: 0.013222136 | AZ12: 0.24537624 | BA12: 0.0057544 | BB12: 0.78679383 | BC12: 0.011949649 | BE12: 0.30357838 | BF12: 0.05487683 | BG12: 0.29560709 | BH12: 0.056465365
B13: 2013 | C13: 0.53930414 | D13: 0.0079249078 | E13: 0.31641114 | F13: 0.04187727 | G13: 0.31205592 | H13: 0.03897693 | J13: 0.5379225 | K13: 0.0047182562 | L13: 0.46041575 | M13: 0.027309746 | N13: 0.50545752 | O13: 0.020477921 | Q13: 0.53732699 | R13: 0.0042502242 | S13: 0.39075041 | T13: 0.02645351 | U13: 0.42264134 | V13: 0.016584203 | Y13: -0.00033112793 | Z13: 0.010157965 | AA13: 0.34350401 | AB13: 0.0085696327 | AC13: 0.91235042 | AD13: 0.014682082 | AF13: 0.18969752 | AG13: 0.058919825 | AH13: 0.21133366 | AI13: 0.053597804 | AK13: 0.098446943 | AL13: 0.033947155 | AM13: 0.096019566 | AN13: 0.035666116 | AP13: 0.10342873 | AQ13: 0.019900111 | AR13: 0.11078888 | AS13: 0.024392538 | AU13: -0.042559624 | AV13: 0.013956625 | AW13: -0.055673793 | AX13: 0.011065315 | AZ13: 0.34304756 | BA13: 0.0055036508 | BB13: 0.9118939 | BC13: 0.012506484 | BE13: 0.097863831 | BF13: 0.045906521 | BG13: 0.11856568 | BH13: 0.057406195
B14: 2014 | C14: 0.53889292 | D14: 0.0073369653 | E14: 0.33299994 | F14: 0.049448695 | G14: 0.27568087 | H14: 0.038941368 | J14: 0.54350638 | K14: 0.0057843584 | L14: 0.43511653 | M14: 0.028313264 | N14: 0.5076316 | O14: 0.015602023 | Q14: 0.54159933 | R14: 0.0040298714 | S14: 0.37783593 | T14: 0.023965785 | U14: 0.41547108 | V14: 0.015781749 | Y14: 0.023645841 | Z14: 0.0089019975 | AA14: 0.2593922 | AB14: 0.0081009623 | AC14: 0.89708513 | AD14: 0.014270289 | AF14: 0.16599262 | AG14: 0.08050134 | AH14: 0.17646593 | AI14: 0.055423461 | AK14: 0.047835227 | AL14: 0.035165846 | AM14: 0.061006386 | AN14: 0.034435481 | AP14: 0.077038921 | AQ14: 0.023898074 | AR14: 0.10204235 | AS14: 0.01755948 | AU14: -0.048841 | AV14: 0.014750977 | AW14: -0.080509216 | AX14: 0.0096326135 | AZ14: 0.2760385 | BA14: 0.0049135881 | BB14: 0.91373146 | BC14: 0.011331852 | BE14: 0.16529195 | BF14: 0.052488167 | BG14: 0.19959188 | BH14: 0.050488133
B15: 2015 | C15: 0.51517719 | D15: 0.0073728291 | E15: 0.32924926 | F15: 0.034029067 | G15: 0.32236409 | H15: 0.040116139 | J15: 0.52937728 | K15: 0.0056695398 | L15: 0.43818375 | M15: 0.033654977 | N15: 0.50443107 | O15: 0.018459763 | Q15: 0.52408683 | R15: 0.0033026054 | S15: 0.39432409 | T15: 0.027094238 | U15: 0.4360387 | V15: 0.01894233 | Y15: 0.01614644 | Z15: 0.0085084252 | AA15: 0.37972242 | AB15: 0.007004587 | AC15: 1.0482934 | AD15: 0.014546688 | AF15: 0.20900203 | AG15: 0.064359277 | AH15: 0.2641018 | AI15: 0.05163775 | AK15: 0.060805399 | AL15: 0.038838685 | AM15: 0.1045711 | AN15: 0.035231162 | AP15: 0.074702114 | AQ15: 0.02516273 | AR15: 0.090319619 | AS15: 0.026139172 | AU15: -0.045343399 | AV15: 0.012868552 | AW15: -0.066853687 | AX15: 0.010902977 | AZ15: 0.39182243 | BA15: 0.0052250265 | BB15: 1.0603935 | BC15: 0.013166622 | BE15: 0.098977037 | BF15: 0.062954001 | BG15: 0.18012568 | BH15: 0.05540536
... B20: 2020 | C20: 0.53873837 | D20: 0.0087576136 | E20: 0.40454856 | F20: 0.054804899 | G20: 0.3357079 | H20: 0.038786322 | J20: 0.53457695 | K20: 0.0054925 | L20: 0.52449858 | M20: 0.064647138 | N20: 0.49100244 | O20: 0.017866902 | Q20: 0.52939576 | R20: 0.0047465279 | S20: 0.47935492 | T20: 0.047574591 | U20: 0.42678636 | V20: 0.015347691 | Y20: 0.083656348 | Z20: 0.0081382617 | AA20: 0.5965969 | AB20: 0.0094985031 | AC20: 1.6764889 | AD20: 0.027624087 | AF20: 0.5049634 | AG20: 0.18703797 | AH20: 0.25316226 | AI20: 0.047936194 | AK20: 0.11445043 | AL20: 0.041053094 | AM20: 0.097806565 | AN20: 0.047983993 | AP20: 0.038417727 | AQ20: 0.02762269 | AR20: 0.018262491 | AS20: 0.033460304 | AU20: -0.039020538 | AV20: 0.018063694 | AW20: -0.033930816 | AX20: 0.01173847 | AZ20: 0.66065872 | BA20: 0.0042338399 | BB20: 1.7405506 | BC20: 0.019928297 | BE20: 0.051900137 | BF20: 0.077578157 | BG20: 0.12176801 | BH20: 0.072529703

Sheet Income Moments YO
B1: YO Diff | J1: Rural-Urban | N1: Rural-Agr | R1: Rural-Farming
B2: Urban | D2: Rural | F2: Nonagr | H2: Farming | J2: Young | L2: Old | N2: Young | P2: Old | R2: Young | T2: Old
A4: 2004 | B4: -0.16644476 | C4: 0.024291221 | D4: -0.070901185 | E4: 0.016231533 | F4: -0.14905961 | G4: 0.013270088 | H4: 0.071850941 | I4: 0.014404536 | J4: -0.15194915 | K4: 0.011569154 | L4: -0.056405574 | M4: 0.02728123 | N4: 0.44737354 | O4: 0.010023859 | P4: 0.51827472 | Q4: 0.015089789 | R4: 0.40077257 | S4: 0.015528258 | T4: 0.54352468 | U4: 0.018974388
A5: 2005 | B5: -0.18125296 | C5: 0.020199705 | D5: -0.037442006 | E5: 0.017793993 | F5: -0.12513541 | G5: 0.012706587 | H5: 0.11826544 | I5: 0.014376766 | J5: -0.13622157 | K5: 0.011130732 | L5: 0.0075893784 | M5: 0.023069043 | N5: 0.47121283 | O5: 0.0085413465 | P5: 0.50865483 | Q5: 0.015322915 | R5: 0.50300008 | S5: 0.016153799 | T5: 0.65870756 | U5: 0.01646922
A6: 2006 | B6: -0.11285067 | C6: 0.017388806 | D6: 0.013794143 | E6: 0.019429304 | F6: -0.071581863 | G6: 0.012070512 | H6: 0.11538034 | I6: 0.01419816 | J6: -0.12418086 | K6: 0.010073946 | L6: 0.002463944 | M6: 0.018812949 | N6: 0.41354918 | O6: 0.0080974521 | P6: 0.39975503 | Q6: 0.013801035 | R6: 0.56164604 | S6: 0.015571239 | T6: 0.66323227 | U6: 0.018584788
A7: 2007 | B7: -0.13839923 | C7: 0.01835046 | D7: -0.014191955 | E7: 0.016166253 | F7: -0.095581017 | G7: 0.011955243 | H7: 0.10724524 | I7: 0.018807663 | J7: -0.12115204 | K7: 0.010381116 | L7: 0.0030552363 | M7: 0.021659169 | N7: 0.31909049 | O7: 0.0096842516 | P7: 0.33328244 | Q7: 0.014619953 | R7: 0.49841163 | S7: 0.016697071 | T7: 0.61984879 | U7: 0.016951814
A8: 2008 | B8: -0.15379457 | C8: 0.017801959 | D8: -0.029791133 | E8: 0.013745195 | F8: -0.11044815 | G8: 0.010720891 | H8: 0.14154902 | I8: 0.018839978 | J8: -0.11765665 | K8: 0.0098077022 | L8: 0.0063467924 | M8: 0.020167094 | N8: 0.31691614 | O8: 0.0084322328 | P8: 0.34670728 | Q8: 0.013653322 | R8: 0.55978179 | S8: 0.018023208 | T8: 0.7311219 | U8: 0.016934281
A9: 2009 | B9: -0.10431527 | C9: 0.018993339 | D9: -0.048020318 | E9: 0.021843387 | F9: -0.089575715 | G9: 0.013557693 | H9: 0.14459655 | I9: 0.021413948 | J9: -0.059414692 | K9: 0.012612595 | L9: -0.0031197439 | M9: 0.023820553 | N9: 0.45770946 | O9: 0.012387256 | P9: 0.50572979 | Q9: 0.018256195 | R9: 0.61662883 | S9: 0.019422878 | T9: 0.80924571 | U9: 0.021071469
A10: 2010 | B10: -0.10061501 | C10: 0.016900212 | D10: -0.035175599 | E10: 0.020072915 | F10: -0.077303723 | G10: 0.012267982 | H10: 0.13689572 | I10: 0.023657046 | J10: -0.030676382 | K10: 0.011582946 | L10: 0.034763031 | M10: 0.021718722 | N10: 0.29405269 | O10: 0.010056411 | P10: 0.32922828 | Q10: 0.01691773 | R10: 0.5154888 | S10: 0.022845965 | T10: 0.68756008 | U10: 0.018480502
A11: 2011 | B11: -0.094910942 | C11: 0.014018943 | D11: -0.03307445 | E11: 0.019297404 | F11: -0.074057095 | G11: 0.011471402 | H11: 0.18267569 | I11: 0.024214175 | J11: -0.033033535 | K11: 0.012920357 | L11: 0.028802961 | M11: 0.023111798 | N11: 0.28806192 | O11: 0.0095216203 | P11: 0.32113639 | Q11: 0.020743096 | R11: 0.55231482 | S11: 0.023779446 | T11: 0.76806492 | U11: 0.020990694
A12: 2012 | B12: -0.074354358 | C12: 0.015797984 | D12: -0.026166558 | E12: 0.01859864 | F12: -0.054944452 | G12: 0.012552189 | H12: 0.16300552 | I12: 0.026355658 | J12: -0.0056582205 | K12: 0.013165109 | L12: 0.042529576 | M12: 0.023772249 | N12: 0.23710585 | O12: 0.011522139 | P12: 0.2632724 | Q12: 0.017924346 | R12: 0.66026139 | S12: 0.024043966 | T12: 0.84943348 | U12: 0.022960328
A13: 2013 | B13: -0.032725889 | C13: 0.016588021 | D13: -0.024756279 | E13: 0.018012298 | F13: -0.028979976 | G13: 0.011131108 | H13: 0.20985538 | I13: 0.028950624 | J13: 0.0027178114 | K13: 0.011873471 | L13: 0.010687422 | M13: 0.017842198 | N13: 0.33500341 | O13: 0.010468638 | P13: 0.35975969 | Q13: 0.014858742 | R13: 0.74558914 | S13: 0.028461332 | T13: 0.98020077 | U13: 0.02028151
A14: 2014 | B14: -0.046370633 | C14: 0.013025417 | D14: 0.0059222425 | E14: 0.01728214 | F14: -0.022780055 | G14: 0.011376967 | H14: 0.17899527 | I14: 0.031037623 | J14: 0.011327997 | K14: 0.01153819 | L14: 0.063620873 | M14: 0.017703267 | N14: 0.26179755 | O14: 0.0092300344 | P14: 0.25587532 | Q14: 0.013752142 | R14: 0.76427346 | S14: 0.024258194 | T14: 0.93734646 | U14: 0.021194337
A15: 2015 | B15: -0.012489721 | C15: 0.012778806 | D15: 0.004478781 | E15: 0.016917298 | F15: -0.0014170306 | G15: 0.0077983513 | H15: 0.16205277 | I15: 0.027869966 | J15: 0.014411571 | K15: 0.012514946 | L15: 0.031380072 | M15: 0.016039601 | N15: 0.38022068 | O15: 0.0096948538 | P15: 0.3757419 | Q15: 0.013442263 | R15: 0.92286563 | S15: 0.023330811 | T15: 1.0804397 | U15: 0.018992456
... A20: 2020 | B20: -0.0081315553 | C20: 0.010213219 | D20: 0.0012147889 | E20: 0.018402388 | F20: 0.0017538483 | G20: 0.0094852112 | H20: 0.37036619 | I20: 0.051791534 | J20: 0.082883142 | K20: 0.012646796 | L20: 0.092229486 | M20: 0.015193158 | N20: 0.59660071 | O20: 0.01104927 | P20: 0.59538591 | Q20: 0.014431071 | R20: 1.3675916 | S20: 0.060602624 | T20: 1.736743 | U20: 0.030543311

Sheet Agr Moments Raw
C1: Raw TFPQ and TFPR (Entire Sample) | R1: Raw TFPQ and TFPR (Top Sample) | AG1: Raw TFPQ and TFPR (Rental Sample)
C2: Disp TFPR | E2: Disp TFPQ | G2: Disp Land | I2: TFPQ Vs. TFPR | M2: TFPQ Vs. Land | R2: Disp TFPR | T2: Disp TFPQ | V2: Disp Land | X2: TFPQ Vs. TFPR | AB2: TFPQ Vs. Land | AG2: Disp TFPR | AI2: Disp TFPQ | AK2: Disp Land | AM2: TFPQ Vs. TFPR | AQ2: TFPQ Vs. Land
I3: Linear Corr | K3: Rank Corr | M3: Linear Corr | O3: Rank Corr | X3: Linear Corr | Z3: Rank Corr | AB3: Linear Corr | AD3: Rank Corr | AM3: Linear Corr | AO3: Rank Corr | AQ3: Linear Corr | AS3: Rank Corr
A4: 2003
A5: 2004 | C5: 0.72698873 | D5: 0.0058352356 | E5: 0.80552006 | F5: 0.006671499 | G5: 0.81855047 | H5: 0.0051142466 | I5: 0.98043877 | J5: 0.00052277051 | K5: 0.96671349 | L5: 0.00085763138 | M5: 0.16569611 | N5: 0.0095503023 | O5: 0.22972393 | P5: 0.010806657 | R5: 0.41272038 | S5: 0.0064964476 | T5: 0.3883971 | U5: 0.0059526945 | V5: 0.84092385 | W5: 0.011750541 | X5: 0.92525536 | Y5: 0.0033427023 | Z5: 0.85291266 | AA5: 0.006885644 | AB5: -0.1401765 | AC5: 0.016526703 | AD5: -0.093459733 | AE5: 0.017454168 | AG5: 0.70677161 | AH5: 0.013143326 | AI5: 0.81295049 | AJ5: 0.01563417 | AK5: 0.85290402 | AL5: 0.012698641 | AM5: 0.9818297 | AN5: 0.0012773318 | AO5: 0.96842414 | AP5: 0.001613259 | AQ5: 0.17836034 | AR5: 0.022335401 | AS5: 0.26526624 | AT5: 0.021211507
A6: 2005 | C6: 0.73107886 | D6: 0.0055860551 | E6: 0.80306703 | F6: 0.0055558388 | G6: 0.82147187 | H6: 0.005006643 | I6: 0.97999829 | J6: 0.00051304023 | K6: 0.96597677 | L6: 0.0010180774 | M6: 0.2001285 | N6: 0.0091896812 | O6: 0.25893149 | P6: 0.0087754382 | R6: 0.42080313 | S6: 0.0061512752 | T6: 0.39971435 | U6: 0.0058481391 | V6: 0.81766516 | W6: 0.011369368 | X6: 0.91630048 | Y6: 0.0036926253 | Z6: 0.85324222 | AA6: 0.0063311984 | AB6: -0.026298184 | AC6: 0.016733412 | AD6: 0.025221404 | AE6: 0.017768888 | AG6: 0.71568966 | AH6: 0.013982496 | AI6: 0.79907691 | AJ6: 0.014570168 | AK6: 0.85154623 | AL6: 0.011426888 | AM6: 0.97995877 | AN6: 0.001468856 | AO6: 0.96991533 | AP6: 0.0017412388 | AQ6: 0.26885867 | AR6: 0.019630997 | AS6: 0.31995741 | AT6: 0.020650469
A7: 2006 | C7: 0.75570267 | D7: 0.0057783248 | E7: 0.854249 | F7: 0.0075263623 | G7: 0.83001906 | H7: 0.0051657511 | I7: 0.9799999 | J7: 0.00055212958 | K7: 0.96878374 | L7: 0.00092221668 | M7: 0.21071874 | N7: 0.0092729041 | O7: 0.27979678 | P7: 0.0086641796 | R7: 0.40352702 | S7: 0.0056579565 | T7: 0.38995147 | U7: 0.0057549565 | V7: 0.82326597 | W7: 0.011524156 | X7: 0.91229302 | Y7: 0.0043208422 | Z7: 0.86196977 | AA7: 0.0070003169 | AB7: -0.053146511 | AC7: 0.018856088 | AD7: -0.024123758 | AE7: 0.018691646 | AG7: 0.72564864 | AH7: 0.013853521 | AI7: 0.83975786 | AJ7: 0.017586682 | AK7: 0.85053647 | AL7: 0.012719354 | AM7: 0.98096687 | AN7: 0.001154767 | AO7: 0.97007519 | AP7: 0.0017121426 | AQ7: 0.22578289 | AR7: 0.019940967 | AS7: 0.29741836 | AT7: 0.021462796
A8: 2007 | C8: 0.75720704 | D8: 0.007727908 | E8: 0.84926051 | F8: 0.0065471698 | G8: 0.86805528 | H8: 0.005772877 | I8: 0.97970819 | J8: 0.00066388497 | K8: 0.96823221 | L8: 0.00087361271 | M8: 0.14156036 | N8: 0.011457354 | O8: 0.22387268 | P8: 0.011801583 | R8: 0.41190895 | S8: 0.0068594259 | T8: 0.3872503 | U8: 0.0051399176 | V8: 0.87187904 | W8: 0.013431692 | X8: 0.90554214 | Y8: 0.0043054475 | Z8: 0.86568189 | AA8: 0.0077922549 | AB8: -0.1125469 | AC8: 0.020535545 | AD8: -0.09387704 | AE8: 0.020379933 | AG8: 0.76353884 | AH8: 0.014581809 | AI8: 0.87199956 | AJ8: 0.018037323 | AK8: 0.88779622 | AL8: 0.012237977 | AM8: 0.98039961 | AN8: 0.0013956198 | AO8: 0.97267359 | AP8: 0.0018936931 | AQ8: 0.1418308 | AR8: 0.023037519 | AS8: 0.2101533 | AT8: 0.022567486
A9: 2008 | C9: 0.74896884 | D9: 0.0063138693 | E9: 0.83332562 | F9: 0.0069824369 | G9: 0.87751371 | H9: 0.0062579452 | I9: 0.97746849 | J9: 0.0007182291 | K9: 0.96706796 | L9: 0.0010626914 | M9: 0.22022606 | N9: 0.011395259 | O9: 0.2735084 | P9: 0.0093190344 | R9: 0.4082135 | S9: 0.006408724 | T9: 0.38450864 | U9: 0.0056747743 | V9: 0.90083897 | W9: 0.014505045 | X9: 0.89625019 | Y9: 0.0049959165 | Z9: 0.86363137 | AA9: 0.0075510181 | AB9: -0.057808541 | AC9: 0.020454764 | AD9: -0.032525811 | AE9: 0.02129397 | AG9: 0.72982711 | AH9: 0.012226437 | AI9: 0.81661129 | AJ9: 0.014814206 | AK9: 0.88484412 | AL9: 0.012881439 | AM9: 0.97880435 | AN9: 0.0013046354 | AO9: 0.97332704 | AP9: 0.0015142137 | AQ9: 0.27562469 | AR9: 0.021841237 | AS9: 0.33030453 | AT9: 0.021960858
A10: 2009 | C10: 0.8063916 | D10: 0.0074318764 | E10: 0.89984101 | F10: 0.0075223106 | G10: 0.87391174 | H10: 0.0052935625 | I10: 0.98031515 | J10: 0.00065888726 | K10: 0.97020131 | L10: 0.00075322692 | M10: 0.17203718 | N10: 0.010533372 | O10: 0.23506972 | P10: 0.0098423399 | R10: 0.40657443 | S10: 0.0059285928 | T10: 0.39692438 | U10: 0.0059278347 | V10: 0.86465752 | W10: 0.013031758 | X10: 0.90217626 | Y10: 0.0057976292 | Z10: 0.86238319 | AA10: 0.0067425659 | AB10: -0.032006674 | AC10: 0.023459006 | AD10: -0.0092005581 | AE10: 0.021077553 | AG10: 0.82875961 | AH10: 0.015606407 | AI10: 0.92540663 | AJ10: 0.016450893 | AK10: 0.87229955 | AL10: 0.01305432 | AM10: 0.98322582 | AN10: 0.0010287064 | AO10: 0.97679675 | AP10: 0.0017523303 | AQ10: 0.20730273 | AR10: 0.022326574 | AS10: 0.29248649 | AT10: 0.024478501
A11: 2010 | C11: 0.80985075 | D11: 0.0078048129 | E11: 0.90427166 | F11: 0.0096211303 | G11: 0.88306284 | H11: 0.0069155046 | I11: 0.98011899 | J11: 0.0006841573 | K11: 0.97004622 | L11: 0.0010495109 | M11: 0.20781079 | N11: 0.010436113 | O11: 0.24686782 | P11: 0.010865344 | R11: 0.41393638 | S11: 0.0063450122 | T11: 0.40564057 | U11: 0.0058374312 | V11: 0.8982957 | W11: 0.015107181 | X11: 0.90229863 | Y11: 0.0048505422 | Z11: 0.87011975 | AA11: 0.0068712812 | AB11: -0.029530363 | AC11: 0.021807475 | AD11: -0.015153956 | AE11: 0.021362072 | AG11: 0.77726483 | AH11: 0.014687186 | AI11: 0.87222922 | AJ11: 0.015813116 | AK11: 0.85209167 | AL11: 0.013123894 | AM11: 0.9809643 | AN11: 0.0012201628 | AO11: 0.97620881 | AP11: 0.001480176 | AQ11: 0.28784257 | AR11: 0.024505997 | AS11: 0.3120203 | AT11: 0.021257322
A12: 2011 | C12: 0.80242413 | D12: 0.0077318577 | E12: 0.91742361 | F12: 0.0093678618 | G12: 0.91856086 | H12: 0.0068124821 | I12: 0.97938567 | J12: 0.00077282824 | K12: 0.96738368 | L12: 0.0011719908 | M12: 0.22205377 | N12: 0.011761891 | O12: 0.28209803 | P12: 0.011731 | R12: 0.40854481 | S12: 0.006566199 | T12: 0.39401484 | U12: 0.0061241146 | V12: 0.98245269 | W12: 0.017203126 | X12: 0.8883459 | Y12: 0.0066823284 | Z12: 0.84760219 | AA12: 0.008266787 | AB12: -0.0023289656 | AC12: 0.02402525 | AD12: -0.0012591975 | AE12: 0.023660574 | AG12: 0.77133006 | AH12: 0.016857715 | AI12: 0.9024539 | AJ12: 0.021323541 | AK12: 0.91696882 | AL12: 0.017169464 | AM12: 0.97988486 | AN12: 0.0011977628 | AO12: 0.97155464 | AP12: 0.0016977353 | AQ12: 0.30607334 | AR12: 0.025447682 | AS12: 0.34380537 | AT12: 0.018357268
A13: 2012 | C13: 0.79885864 | D13: 0.0066926498 | E13: 0.90547383 | F13: 0.0078386832 | G13: 0.93078965 | H13: 0.0067494782 | I13: 0.97872192 | J13: 0.00083495351 | K13: 0.96809077 | L13: 0.0010743795 | M13: 0.26525223 | N13: 0.01281779 | O13: 0.3197903 | P13: 0.011980062 | R13: 0.36946416 | S13: 0.0062253713 | T13: 0.35915229 | U13: 0.0061385017 | V13: 0.98738307 | W13: 0.015467152 | X13: 0.86737925 | Y13: 0.0073527452 | Z13: 0.82686532 | AA13: 0.0084244935 | AB13: 0.11346215 | AC13: 0.026585117 | AD13: 0.10288314 | AE13: 0.02412622 | AG13: 0.7995646 | AH13: 0.017403748 | AI13: 0.89183742 | AJ13: 0.019405019 | AK13: 0.95332044 | AL13: 0.017163308 | AM13: 0.98139763 | AN13: 0.001238907 | AO13: 0.9767803 | AP13: 0.0016492436 | AQ13: 0.33367455 | AR13: 0.026260521 | AS13: 0.3960577 | AT13: 0.021786019
A14: 2013 | C14: 0.8718341 | D14: 0.0090783434 | E14: 0.99057204 | F14: 0.011288138 | G14: 0.96731097 | H14: 0.0076605654 | I14: 0.98139274 | J14: 0.00080989761 | K14: 0.97097564 | L14: 0.0011910468 | M14: 0.27010813 | N14: 0.011438278 | O14: 0.33061031 | P14: 0.010460013 | R14: 0.40825376 | S14: 0.0071093701 | T14: 0.39248338 | U14: 0.0062051602 | V14: 1.0167968 | W14: 0.019148404 | X14: 0.88922602 | Y14: 0.0062041949 | Z14: 0.83679688 | AA14: 0.0091545628 | AB14: -0.0041445354 | AC14: 0.023429142 | AD14: 0.016391102 | AE14: 0.026741443 | AG14: 0.80742127 | AH14: 0.020057412 | AI14: 0.91433454 | AJ14: 0.020024998 | AK14: 0.98088807 | AL14: 0.015220812 | AM14: 0.97951227 | AN14: 0.0014446554 | AO14: 0.97052425 | AP14: 0.0021130037 | AQ14: 0.32872787 | AR14: 0.024936805 | AS14: 0.3850413 | AT14: 0.026302258
A15: 2014 | C15: 0.93668556 | D15: 0.0091143334 | E15: 1.0763597 | F15: 0.01133487 | G15: 0.9927727 | H15: 0.0068064197 | I15: 0.98245108 | J15: 0.00051976973 | K15: 0.97351211 | L15: 0.00088424445 | M15: 0.23764248 | N15: 0.011307818 | O15: 0.29179814 | P15: 0.011400823 | R15: 0.43673801 | S15: 0.0073478217 | T15: 0.42424795 | U15: 0.0060868603 | V15: 1.032442 | W15: 0.021295862 | X15: 0.89959687 | Y15: 0.0052948999 | Z15: 0.87341201 | AA15: 0.0067578927 | AB15: 0.037380252 | AC15: 0.021246303 | AD15: 0.037001461 | AE15: 0.021219345 | AG15: 0.89342856 | AH15: 0.025740897 | AI15: 1.0192751 | AJ15: 0.022444669 | AK15: 0.95230591 | AL15: 0.015060246 | AM15: 0.98460007 | AN15: 0.0012939775 | AO15: 0.97720206 | AP15: 0.0016353362 | AQ15: 0.27265367 | AR15: 0.026102548 | AS15: 0.32578319 | AT15: 0.0236948
A16: 2015 | C16: 0.97202796 | D16: 0.010300096 | E16: 1.1202335 | F16: 0.010179531 | G16: 1.0263993 | H16: 0.0071453601 | I16: 0.98332787 | J16: 0.00057651644 | K16: 0.973189 | L16: 0.0010085424 | M16: 0.22408514 | N16: 0.010708149 | O16: 0.27164167 | P16: 0.013955968 | R16: 0.45878738 | S16: 0.0069419025 | T16: 0.45071816 | U16: 0.0074021262 | V16: 1.1013354 | W16: 0.017876213 | X16: 0.89394593 | Y16: 0.0072005196 | Z16: 0.86933112 | AA16: 0.0078610182 | AB16: 0.040318642 | AC16: 0.030141031 | AD16: 0.034200687 | AE16: 0.023030588 | AG16: 0.88716769 | AH16: 0.019932734 | AI16: 1.0569236 | AJ16: 0.023780307 | AK16: 1.00927 | AL16: 0.014670786 | AM16: 0.9819088 | AN16: 0.0014416947 | AO16: 0.96976119 | AP16: 0.0018650314 | AQ16: 0.24609022 | AR16: 0.030266121 | AS16: 0.31323498 | AT16: 0.028298391
... A21: 2020 | C21: 1.1069926 | D21: 0.012296137 | E21: 1.2605935 | F21: 0.017267976 | G21: 1.1237683 | H21: 0.0096676731 | I21: 0.98488981 | J21: 0.00060244213 | K21: 0.97821051 | L21: 0.00093536807 | M21: 0.28278831 | N21: 0.01499275 | O21: 0.32344416 | P21: 0.0123686 | R21: 0.56681186 | S21: 0.016191326 | T21: 0.52925962 | U21: 0.012716338 | V21: 1.1483026 | W21: 0.021430518 | X21: 0.93022412 | Y21: 0.0054458743 | Z21: 0.89193708 | AA21: 0.0082405861 | AB21: -0.038615923 | AC21: 0.030021435 | AD21: -0.039914358 | AE21: 0.03744261 | AG21: 0.96094936 | AH21: 0.033843044 | AI21: 1.0786227 | AJ21: 0.032594189 | AK21: 1.1600814 | AL21: 0.020866022 | AM21: 0.9799844 | AN21: 0.0015099478 | AO21: 0.97350544 | AP21: 0.0027066569 | AQ21: 0.23687606 | AR21: 0.035319839 | AS21: 0.27673244 | AT21: 0.031220177

Sheet Agr Moments Permanent
C1: Permanent TFPQ and TFPR (Entire Sample) | R1: Permanent TFPQ and TFPR (Top Sample) | AG1: Permanent TFPQ and TFPR (Rental Sample)
C2: Disp TFPR | E2: Disp TFPQ | G2: Disp Land | I2: TFPQ Vs. TFPR | M2: TFPQ Vs. Land | R2: Disp TFPR | T2: Disp TFPQ | V2: Disp Land | X2: TFPQ Vs. TFPR | AB2: TFPQ Vs. Land | AG2: Disp TFPR | AI2: Disp TFPQ | AK2: Disp Land | AM2: TFPQ Vs. TFPR | AQ2: TFPQ Vs. Land
I3: Linear Corr | K3: Rank Corr | M3: Linear Corr | O3: Rank Corr | X3: Linear Corr | Z3: Rank Corr | AB3: Linear Corr | AD3: Rank Corr | AM3: Linear Corr | AO3: Rank Corr | AQ3: Linear Corr | AS3: Rank Corr
A4: 2003
A5: 2004 | C5: 0.63291216 | D5: 0.0044705141 | E5: 0.65733647 | F5: 0.0046475721 | G5: 0.81855047 | H5: 0.0059401505 | I5: 0.97126907 | J5: 0.00072051247 | K5: 0.96269286 | L5: 0.0010201802 | M5: 0.25204828 | N5: 0.0097220894 | O5: 0.29074055 | P5: 0.0095156347 | R5: 0.32202321 | S5: 0.004624607 | T5: 0.30667481 | U5: 0.0044559408 | V5: 0.84162152 | W5: 0.011989327 | X5: 0.87283832 | Y5: 0.0051893531 | Z5: 0.82377785 | AA5: 0.0072765425 | AB5: 0.024760505 | AC5: 0.019363036 | AD5: 0.057110123 | AE5: 0.017672425 | AG5: 0.64787775 | AH5: 0.010795107 | AI5: 0.67936164 | AJ5: 0.010200755 | AK5: 0.85290402 | AL5: 0.011869663 | AM5: 0.97237873 | AN5: 0.001373116 | AO5: 0.96783692 | AP5: 0.0015279254 | AQ5: 0.33172283 | AR5: 0.020311644 | AS5: 0.35314858 | AT5: 0.020586941
